Workbook

Sheet Assumption 1_GSKCH
A1: Assumptions: Standalone DCF Valuation of GlaxoSmithKline Consumer Healthcare (without merger)
A2: Particulars | B2: Values in %
A3: Growth ratea | B3: -0.02
A4: Terminal growth rateb | B4: 0.02
A5: Cost of capital (WACC)c | B5: 0.06
A8: Note: DCF = discounted cash flow; CER = constant exchange rate; WACC = weighted average cost of capital.
A10: Source:
A11: a Proforma CER growth rate of consumer healthcare division as per GSK annual report 2020
A12: b Terminal growth rate of consumer healthcare division as per GSK annual report 2020
A13: c Discount rate of consumer healthcare division as per GSK annual report 2020

Sheet Income statement_GSKCH
A1: GSKCH Standalone Valuation
A2: (in INR millions)
C3: Historical Period | I3: FORECAST PERIOD
C4: 2017 | D4: 2018 | E4: 2019 | I4: 2020 | J4: 2021 | K4: 2022 | L4: 2023 | M4: 2024 | N4: 2025
A5: Total Revenue | C5: 44211 | D5: 43771 | E5: 47820 | G5: YoY Growth | H5: ='Assumption 1_GSKCH'!B3 -> -0.02 | I5: =$E$5*(1+H5) -> 46863.6 | J5: =I5*(1+$H$5) -> 45926.328 | K5: =J5*(1+$H$5) -> 45007.801 | L5: =K5*(1+$H$5) -> 44107.645 | M5: =L5*(1+$H$5) -> 43225.493
A6: % growth | E6: =(E5/D5)-1 -> 0.092504169
A7: Cost of Goods Sold | C7: 19393 | D7: 16998 | E7: 16575 | I7: =$E$8*I5 -> 16243.5 | J7: =$E$8*J5 -> 15918.63 | K7: =$E$8*K5 -> 15600.257 | L7: =$E$8*L5 -> 15288.252 | M7: =$E$8*M5 -> 14982.487
A8: % of sales | E8: =E7/E5 -> 0.3466123
A9: Gross Profit | C9: =C5-C7 -> 24818 | D9: =D5-D7 -> 26773 | E9: =E5-E7 -> 31245 | I9: =I5-I7 -> 30620.1 | J9: =J5-J7 -> 30007.698 | K9: =K5-K7 -> 29407.544 | L9: =L5-L7 -> 28819.393 | M9: =M5-M7 -> 28243.005
A10: Selling, General & Administrative | C10: 16483 | D10: 17939 | E10: 19835 | I10: =$H$11*I5 -> 18705.574 | J10: =$H$11*J5 -> 18331.462 | K10: =$H$11*K5 -> 17964.833 | L10: =$H$11*L5 -> 17605.536 | M10: =$H$11*M5 -> 17253.426
A11: SG&A as a % of sales | C11: =C10/C5 -> 0.37282577 | D11: =D10/D5 -> 0.40983756 | E11: =E10/E5 -> 0.41478461 | G11: Average SG&A EXP | H11: =AVERAGE(C11:E11) -> 0.39914931
A12: EBITDA | C12: =C9-C10 -> 8335 | D12: =D9-D10 -> 8834 | E12: =E9-E10 -> 11410 | F12: =E12/E5 -> 0.23860309 | I12: =I9-I10 -> 11914.526 | J12: =J9-J10 -> 11676.236 | K12: =K9-K10 -> 11442.711 | L12: =L9-L10 -> 11213.857 | M12: =M9-M10 -> 10989.58
A13: Depreciation & Amortization | C13: =[1]Schedules!E21 -> 642 | D13: =[1]Schedules!F21 -> 644 | E13: =[1]Schedules!G21 -> 605 | G13: AVERAGE DEP | H13: =AVERAGE(C13:E13) -> 630.33333 | I13: =$H$13 -> 630.33333 | J13: =$H$13 -> 630.33333 | K13: =$H$13 -> 630.33333 | L13: =$H$13 -> 630.33333 | M13: =$H$13 -> 630.33333
A14: % of sales | C14: =C13/C5 -> 0.014521273 | D14: =D13/D5 -> 0.014712938 | E14: =E13/E5 -> 0.01265161 | I14: =I13/I5 -> 0.013450382 | J14: =J13/J5 -> 0.01372488 | K14: =K13/K5 -> 0.014004979 | L14: =L13/L5 -> 0.014290795 | M14: =M13/M5 -> 0.014582444
A15: Operating income | C15: =C12-C13 -> 7693 | D15: =D12-D13 -> 8190 | E15: =E12-E13 -> 10805 | I15: =I12-I13 -> 11284.193 | J15: =J12-J13 -> 11045.902 | K15: =K12-K13 -> 10812.378 | L15: =L12-L13 -> 10583.523 | M15: =M12-M13 -> 10359.246
A16: Interest income (expense) – net no recurring | C16: 2183 | D16: 2164 | E16: 2748 | F16: Nonrecurring
A17: Gain (loss) on sale of asset | C17: 0 | D17: 4 | E17: 4 | F17: Nonrecurring
A18: Other income (expense) | C18: 226 | D18: 385 | E18: 1565 | F18: Nonrecurring
A19: EBIT | C19: =SUM(C15:C18) -> 10102 | D19: =SUM(D15:D18) -> 10743 | E19: =SUM(E15:E18) -> 15122 | H19: =I19/I5 -> 0.24078801 | I19: =I15-I16-I17-I18 -> 11284.193 | J19: =J15-J16-J17-J18 -> 11045.902 | K19: =K15-K16-K17-K18 -> 10812.378 | L19: =L15-L16-L17-L18 -> 10583.523 | M19: =M15-M16-M17-M18 -> 10359.246
A20: Interest expense* | C20: 0 | D20: 0 | E20: 0
A21: PBT | C21: =C19-C20 -> 10102 | D21: =D19-D20 -> 10743 | E21: =E19-E20 -> 15122 | I21: =I19-I20 -> 11284.193 | J21: =J19-J20 -> 11045.902 | K21: =K19-K20 -> 10812.378 | L21: =L19-L20 -> 10583.523 | M21: =M19-M20 -> 10359.246
A22: Tax % | E22: =E23/E21 -> 0.3501521
A23: Taxes | C23: 3537 | D23: 3743 | E23: 5295 | I23: =$E$22*I21 -> 3951.1838 | J23: =$E$22*J21 -> 3867.7459 | K23: =$E$22*K21 -> 3785.9767 | L23: =$E$22*L21 -> 3705.8429 | M23: =$E$22*M21 -> 3627.3118
A24: Net Income (EBIT*(1-t)) | C24: =C21*(1-C22) -> 10102 | D24: =D21*(1-D22) -> 10743 | E24: =E21*(1-E22) -> 9827 | I24: =I21-I23 -> 7333.0091 | J24: =J21-J23 -> 7178.1565 | K24: =K21-K23 -> 7026.401 | L24: =L21-L23 -> 6877.6805 | M24: =M21-M23 -> 6731.9345 | N24: =M24*(1+B30) -> 6866.5732
A25: Plus: Depreciation & Amortization | C25: =C13 -> 642 | D25: =D13 -> 644 | E25: =E13 -> 605 | I25: =I13 -> 630.33333 | J25: =J13 -> 630.33333 | K25: =K13 -> 630.33333 | L25: =L13 -> 630.33333 | M25: =M13 -> 630.33333
A26: Less (plus): Increase (Decrease) in Capital Expenditures | C26: 4874 | D26: 4755.3 | E26: 4620.7 | G26: Average CAPEX (% of revenue) | H26: =AVERAGE((((D26-C26)+D25)/D5),(((E26-D26)+E25)/E5)) -> 0.010918992 | I26: =$H$26*I5 -> 511.7033 | J26: =$H$26*J5 -> 501.46923 | K26: =$H$26*K5 -> 491.43985 | L26: =$H$26*L5 -> 481.61105 | M26: =$H$26*M5 -> 471.97883
A27: Less: Increase/(Decrease) in Net Working Capital | C27: 25518.7 | D27: 28194.1 | E27: =[2]TN3_Schedules!D8 -> 34534.4 | G27: Average NWC (% of revenue) | H27: =AVERAGE((C27/$C$5),(D27/$D$5),(E27/$E$5)) -> 0.64783491 | I27: =$H$27*I5 -> 30359.876 | J27: =$H$27*J5 -> 29752.678 | K27: =$H$27*K5 -> 29157.625 | L27: =$H$27*L5 -> 28574.472 | M27: =$H$27*M5 -> 28002.983
A28: Unlevered Free Cash Flow to Firm | I28: =I24+I25-I26-(I27-E27) -> 11626.163 | J28: =J24+J25-J26-(J27-I27) -> 7914.2181 | K28: =K24+K25-K26-(K27-J27) -> 7760.348 | L28: =L24+L25-L26-(L27-K27) -> 7609.5553 | M28: =M24+M25-M26-(M27-L27) -> 7461.7785 | N28: =M28*(1+B30) -> 7611.014
A30: Terminal growth rate | B30: 0.02
A31: Discount factor | B31: 0.06
A32: Present value of free cash flow | B32: =NPV(B31,I28:M28) -> 36130.798
A33: Terminal value | B33: =N28/(B31-B30) -> 190275.35
A34: Present value of perpetuity | B34: =B33/((1+B31)^6) -> 134136.61
A35: EV | B35: =B34+B32 -> 170267.41
A36: No. of shares in million | B36: 42.06
A37: Price per share | B37: =B35/B36 -> 4048.2028
A42: Sensitivity Analysis
A45: Terminal Growth Rate | B45: Value per Share
B46: WACC
B47: =B37 -> 4048.2028 | C47: 0.05 | D47: 0.06 | E47: 0.07
...

Sheet Assumption 2-HUL_with synergy
A1: GSKCH Standalone Valuation
A2: (in INR millions)
C3: Historical Period | I3: FORECAST PERIOD
C4: 2017 | D4: 2018 | E4: 2019 | I4: 2020 | J4: 2021 | K4: 2022 | L4: 2023 | M4: 2024 | N4: 2025
A5: Total Revenue | C5: 44211 | D5: 43771 | E5: 47820 | G5: GROWTH RATE (CAGR) | H5: 0.11 | I5: =E5*(1+H5) -> 53080.2 | J5: =I5*(1+$H$5) -> 58919.022 | K5: =J5*(1+$H$5) -> 65400.114 | L5: =K5*(1+$H$5) -> 72594.127 | M5: =L5*(1+$H$5) -> 80579.481
A6: % growth | E6: =(E5/D5)-1 -> 0.092504169
A7: Cost of Goods Sold | C7: 19393 | D7: 16998 | E7: 16575
A8: % of sales | E8: =E7/E5 -> 0.3466123
A9: Gross Profit | C9: =C5-C7 -> 24818 | D9: =D5-D7 -> 26773 | E9: =E5-E7 -> 31245
A10: Selling, General & Administrative | C10: 16483 | D10: 17939 | E10: 19835
A11: SG&A as a % of sales | C11: =C10/C5 -> 0.37282577 | D11: =D10/D5 -> 0.40983756 | E11: =E10/E5 -> 0.41478461 | G11: Average SG&A EXP | H11: =AVERAGE(C11:E11) -> 0.39914931
A12: EBITDA | C12: =C9-C10 -> 8335 | D12: =D9-D10 -> 8834 | E12: =E9-E10 -> 11410
A13: Depreciation & Amortization | C13: =[1]Schedules!E21 -> 642 | D13: =[1]Schedules!F21 -> 644 | E13: =[1]Schedules!G21 -> 605 | G13: AVERAGE DEP | H13: =AVERAGE(C13:E13) -> 630.33333
A14: % of sales | C14: =C13/C5 -> 0.014521273 | D14: =D13/D5 -> 0.014712938 | E14: =E13/E5 -> 0.01265161
A15: Operating income | C15: =C12-C13 -> 7693 | D15: =D12-D13 -> 8190 | E15: =E12-E13 -> 10805
A16: Interest income (expense) – net no recurring | C16: 2183 | D16: 2164 | E16: 2748 | F16: Nonrecurring
A17: Gain (loss) on sale of asset | C17: 0 | D17: 4 | E17: 4 | F17: Nonrecurring
A18: Other income (expense) | C18: 226 | D18: 385 | E18: 1565 | F18: Nonrecurring
A19: EBIT | C19: =SUM(C15:C18) -> 10102 | D19: =SUM(D15:D18) -> 10743 | E19: =SUM(E15:E18) -> 15122 | G19: EBIT MARGIN | H19: 0.31 | I19: =$H$19*I5 -> 16454.862 | J19: =$H$19*J5 -> 18264.897 | K19: =$H$19*K5 -> 20274.035 | L19: =$H$19*L5 -> 22504.179 | M19: =$H$19*M5 -> 24979.639
A20: Interest expense* | C20: 0 | D20: 0 | E20: 0
A21: PBT | C21: =C19-C20 -> 10102 | D21: =D19-D20 -> 10743 | E21: =E19-E20 -> 15122 | I21: =I19-I20 -> 16454.862 | J21: =J19-J20 -> 18264.897 | K21: =K19-K20 -> 20274.035 | L21: =L19-L20 -> 22504.179 | M21: =M19-M20 -> 24979.639
A22: Tax % | E22: =E23/E21 -> 0.3501521
A23: Taxes | C23: 3537 | D23: 3743 | E23: 5295 | I23: =$E$22*I21 -> 5761.7044 | J23: =$E$22*J21 -> 6395.4919 | K23: =$E$22*K21 -> 7098.996 | L23: =$E$22*L21 -> 7879.8856 | M23: =$E$22*M21 -> 8746.673
A24: Net Income (EBIT*(1-t)) | C24: =C21*(1-C22) -> 10102 | D24: =D21*(1-D22) -> 10743 | E24: =E21*(1-E22) -> 9827 | I24: =I21-I23 -> 10693.158 | J24: =J21-J23 -> 11869.405 | K24: =K21-K23 -> 13175.039 | L24: =L21-L23 -> 14624.294 | M24: =M21-M23 -> 16232.966
A25: Plus: Depreciation & Amortization | C25: =C13 -> 642 | D25: =D13 -> 644 | E25: =E13 -> 605 | I25: =$H$13 -> 630.33333 | J25: =$H$13 -> 630.33333 | K25: =$H$13 -> 630.33333 | L25: =$H$13 -> 630.33333 | M25: =$H$13 -> 630.33333
A26: Less (plus): Increase (Decrease) in Capital Expenditures | C26: 4874 | D26: 4755.3 | E26: 4620.7 | G26: Average CAPEX (% of revenue) | H26: =AVERAGE((((D26-C26)+D25)/D5),(((E26-D26)+E25)/E5)) -> 0.010918992 | I26: =$H$26*I5 -> 579.5823 | J26: =$H$26*J5 -> 643.33636 | K26: =$H$26*K5 -> 714.10336 | L26: =$H$26*L5 -> 792.65473 | M26: =$H$26*M5 -> 879.84675
A27: Less: Increase/(Decrease) in Net Working Capital | C27: 25518.7 | D27: 28194.1 | E27: =[2]TN3_Schedules!D8 -> 34534.4 | G27: Average NWC (% of revenue) | H27: =AVERAGE((C27/$C$5),(D27/$D$5),(E27/$E$5)) -> 0.64783491 | I27: =$H$27*I5 -> 34387.206 | J27: =$H$27*J5 -> 38169.799 | K27: =$H$27*K5 -> 42368.477 | L27: =$H$27*L5 -> 47029.009 | M27: =$H$27*M5 -> 52202.201
A28: Unlevered Free Cash Flow to Firm | I28: =I24+I25-I26-(I27-E27) -> 10891.102 | J28: =J24+J25-J26-(J27-I27) -> 8073.8092 | K28: =K24+K25-K26-(K27-J27) -> 8892.5915 | L28: =L24+L25-L26-(L27-K27) -> 9801.4399 | M28: =M24+M25-M26-(M27-L27) -> 10810.262 | N28: =M28*(1+B30) -> 11188.621
A30: Terminal growth rate | B30: 0.035
A31: Discount factor | B31: 0.06
A32: Present value of free cash flow | B32: =NPV(B31,I28:M28) -> 40768.392
A33: Terminal value | B33: =N28/(B31-B30) -> 447544.83
A34: Present value of perpetuity | B34: =B33/((1+B31)^6) -> 315501.45
A35: EV | B35: =B34+B32 -> 356269.84
A36: No. of shares in million | B36: 42.06
A37: Price per share | B37: =B35/B36 -> 8470.5145
A41: Terminal Growth Rate | B41: Value per Share
B42: WACC
B43: =B37 -> 8470.5145 | C43: 0.05 | D43: 0.055 | E43: 0.065 | F43: 0.07 | G43: 0.075
B44: 0.025 | C44: 8859.9462 | D44: 7351.4856 | E44: 5469.8521 | F44: 4844.2833 | G44: 4344.7519
...

Sheet  Relative valuation
A1: Relative Valuation Based on Target Year 2019–20 (in INR millions)
A3: Company name | B3: Enterprise value | C3: EV/EBITDA | D3: EV/Sales | E3: Market capitalization | F3: Total debt | G3: Cash | H3: Total revenue | I3: EBITDA
A4: GlaxoSmithKline Consumer Healthcare | B4: =E4+F4-G4 -> 264311.5 | C4: =B4/I4 -> 23.423164 | D4: =B4/H4 -> 5.640017 | E4: 300131.7 | F4: 0 | G4: 35820.2 | H4: ='Income statement_GSKCH'!I5 -> 46863.6 | I4: ='Income statement_GSKCH'!I15 -> 11284.193
A5: Nestle | B5: =E5+F5-G5 -> 1442835.7 | C5: =B5/I5 -> 24.108457 | D5: =B5/H5 -> 11.665028 | E5: 1425983 | F5: 29784.3 | G5: 12931.6 | H5: 123689 | I5: =126157.8-51503-2178.1-12629 -> 59847.7
A6: Abbott | B6: =E6+F6-G6 -> 154419.2 | C6: =B6/I6 -> 21.506254 | D6: =B6/H6 -> 4.197771 | E6: 155034.9 | F6: 754.3 | G6: 1370 | H6: 36786 | I6: 7180.2
A7: Mondelēz* | B7: =E7+F7-G7 -> 6347239.7 | C7: =B7/I7 -> 22.40951 | D7: =B7/H7 -> 3.4799366 | E7: 5408117 | F7: 1030151.1 | G7: 91028.41 | H7: 1823952.7 | I7: 283238.67
B9: Minimum | C9: =MIN(C4:C7) -> 21.506254 | D9: =MIN(D4:D7) -> 3.4799366
B10: Median | C10: =MEDIAN(C4:C7) -> 22.916337 | D10: =MEDIAN(D4:D7) -> 4.918894
B11: Maximum | C11: =MAX(C4:C7) -> 24.108457 | D11: =MAX(D4:D7) -> 11.665028
B12: Average | C12: =AVERAGE(C4:C7) -> 22.861846 | D12: =AVERAGE(D4:D7) -> 6.2456883
A15: WITH SYNERGY
A16: Company name | B16: Enterprise value | C16: EV/EBITDA | D16: EV/Sales | E16: Market capitalization | F16: Total debt | G16: Cash | H16: Total revenue | I16: EBITDA
A17: GlaxoSmithKline Consumer Healthcare | B17: ='Assumption 2-HUL_with synergy'!B35 -> 356269.84 | C17: =B17/I17 -> 21.651342 | D17: =B17/H17 -> 6.7119159 | E17: 300131.7 | F17: 0 | G17: 35820.2 | H17: ='Assumption 2-HUL_with synergy'!I5 -> 53080.2 | I17: ='Assumption 2-HUL_with synergy'!I19 -> 16454.862
A18: Nestle | B18: =E18+F18-G18 -> 1442835.7 | C18: =B18/I18 -> 24.108457 | D18: =B18/H18 -> 11.665028 | E18: 1425983 | F18: 29784.3 | G18: 12931.6 | H18: 123689 | I18: =126157.8-51503-2178.1-12629 -> 59847.7
A19: Abbott | B19: =E19+F19-G19 -> 154419.2 | C19: =B19/I19 -> 21.506254 | D19: =B19/H19 -> 4.197771 | E19: 155034.9 | F19: 754.3 | G19: 1370 | H19: 36786 | I19: 7180.2
A20: Mondelēz* | B20: =E20+F20-G20 -> 6347239.7 | C20: =B20/I20 -> 22.40951 | D20: =B20/H20 -> 3.4799366 | E20: 5408117 | F20: 1030151.1 | G20: 91028.41 | H20: 1823952.7 | I20: 283238.67
B22: Minimum | C22: =MIN(C17:C20) -> 21.506254 | D22: =MIN(D17:D20) -> 3.4799366
B23: Median | C23: =MEDIAN(C17:C20) -> 22.030426 | D23: =MEDIAN(D17:D20) -> 5.4548435
B24: Maximum | C24: =MAX(C17:C20) -> 24.108457 | D24: =MAX(D17:D20) -> 11.665028
B25: Average | C25: =AVERAGE(C17:C20) -> 22.418891 | D25: =AVERAGE(D17:D20) -> 6.513663
A34: GSKCH Variables in INR millions
A35: 2019 Sales | B35: 47820
A36: 2019 EBITDA | B36: 11410
A37: EBITDA with synergies (2024) | B37: =0.32*H4 -> 14996.352 | C37: To calculate
A38: 2019 end-of-year cash | B38: 35820.2
A39: 2019 end-of-year debt | B39: 0
A40: Number of common shares | B40: 42.06
A44: Multiple | C44: GSK Value per Share
A45: EV/EBITDA | B45: =C12 -> 22.861846 | C45: =(B45*I4)/B40 -> 6133.5588
A46: EV/Sales | B46: =D12 -> 6.2456883 | C46: =(B46*H4)/B40 -> 6958.9975
A47: EV/EBITDA with synergies | B47: =C25 -> 22.418891 | C47: =(B17-0)/B40 -> 8470.5145
A48: DCF with synergies | C48: ='Assumption 2-HUL_with synergy'!B37 -> 8470.5145
A49: DCF standalone | C49: ='Income statement_GSKCH'!B37 -> 4048.2028

Sheet Strategic Context

Sheet Future Outlook
